Workbook

Sheet Questions
A1: ref | B1: status | C1: chapter | D1: difficulty | E1: title | F1: fact1_label | G1: fact1_value | H1: fact2_label | I1: fact2_value | J1: fact3_label | K1: fact3_value | L1: fact4_label | M1: fact4_value | N1: question | O1: option_A | P1: option_B | Q1: option_C | R1: option_D | S1: answer | T1: explanation | U1: why_not_A | V1: why_not_B | W1: why_not_C | X1: why_not_D | Y1: quote_1_source | Z1: quote_1 | AA1: quote_2_source | AB1: quote_2 | AC1: citation | AD1: verify | AE1: as_of | AF1: reviewer_notes | AG1: check
A2: ONB/ELG/101 | B2: live | C2: II | D2: 1 | E2: Home regulator outside IOSCO | F2: Applicant | G2: Halden Value Fund, a regulated fund | H2: Home regulator | I2: Not an IOSCO MMoU (Appendix A) signatory, and no bilateral MoU with SEBI | J2: Set up in | K2: Its home country, not an IFSC | L2: Requested | M2: Category II | N2: Can the DDP register it? | O2: Yes, as Category II | P2: No. It fails the home-regulator test in Reg 4(d) | Q2: Yes, if its manager is from a FATF member country | R2: Yes, as Category I, because it is regulated | S2: B | T2: Reg 4(d) requires the applicant to be resident in a country whose securities regulator has signed the IOSCO MMoU (Appendix A) or has a bilateral MoU with SEBI. The two exceptions are a government investor from a country approved by the Government of India, and an applicant set up in an IFSC. | U2: Choosing a category doesn't cure eligibility. Reg 4 applies to every category, so Category II is still blocked. | W2: The FATF-manager test only helps an applicant get into Category I under Reg 5. It doesn't override Reg 4(d). | X2: Being regulated affects the category, but the applicant has to pass Reg 4(d) first. | Y2: SEBI (FPI) Regulations, 2019, Regulation 4(d) | Z2: (d) the applicant is a resident of the country whose securities market regulator is a signatory to the International Organization of Securities Commission's Multilateral Memorandum of Understanding (Appendix A Signatories) or a signatory to the bilateral Memorandum of Understanding with the Board: Provided that an applicant being Government or Government related investor shall be considered as eligible for registration, if such applicant is a resident in the country as may be approved by the Government of India; | AC2: FPI Regs 2019, Reg 4(d) and proviso; Op. Guidelines Part A 2(i) | AE2: Oct 2026 | AG2: =IF(A2="","",IF(COUNTA(O2:R2)<4,"Needs 4 options",IF(ISERROR(FIND(UPPER(S2),"ABCD"))+(LEN(S2)<>1),"Answer must be A-D",IF(OR(D2<1,D2>3),"Difficulty must be 1-3",IF(OR(N2="",T2=""),"Missing question or explanation",IF(COUNTBLANK(U2:X2)<>1,"Need 3 why-not texts",IF(INDEX(U2:X2,1,FIND(UPPER(S2),"ABCD"))<>"","Why-not filled for the answer",IF(AND(B2<>"live",B2<>"draft",B2<>"retired"),"Status must be live/draft/retired","OK")))))))) -> OK
A3: ONB/CAT/102 | B3: live | C3: II | D3: 2 | E3: Bank whose central bank isn't in the BIS | F3: Applicant | G3: Commercial bank, licensed by its home banking regulator | H3: Home central bank | I3: Not a member of the Bank for International Settlements | J3: India presence | K3: None | L3: Requested | M3: Category I, as a regulated bank | N3: Where does this applicant land? | O3: Category I, as a bank regulated by its home banking regulator | P3: Category II, which the guidelines allow for such banks | Q3: Not eligible in any category, because of the BIS test | R3: Category I, once RBI approves the application | S3: B | T3: A bank applicant is expected to come from a country whose central bank is a BIS member (Reg 4(e)). The guidelines let a bank regulated at home whose central bank isn't a BIS member seek registration under Category II instead. | U3: Category I for a bank assumes its central bank is a BIS member, which isn't the case here. | W3: Too strict. The guidelines expressly let this bank apply under Category II. | X3: No RBI approval converts this into Category I. RBI is consulted only for banks with an Indian presence. | Y3: SEBI Operational Guidelines for FPIs and DDPs, Part A 3(i) | Z3: In case a bank FPI applicant is regulated by the banking sector regulator in its home jurisdiction, but the central bank of that country is not a member of BIS, the FPI can seek registration under Category II. | AC3: FPI Regs 2019, Reg 4(e); Op. Guidelines Part A 3(i) | AE3: Oct 2026 | AG3: =IF(A3="","",IF(COUNTA(O3:R3)<4,"Needs 4 options",IF(ISERROR(FIND(UPPER(S3),"ABCD"))+(LEN(S3)<>1),"Answer must be A-D",IF(OR(D3<1,D3>3),"Difficulty must be 1-3",IF(OR(N3="",T3=""),"Missing question or explanation",IF(COUNTBLANK(U3:X3)<>1,"Need 3 why-not texts",IF(INDEX(U3:X3,1,FIND(UPPER(S3),"ABCD"))<>"","Why-not filled for the answer",IF(AND(B3<>"live",B3<>"draft",B3<>"retired"),"Status must be live/draft/retired","OK")))))))) -> OK
A4: ONB/BNK/103 | B4: live | C4: II | D4: 2 | E4: Foreign bank with an Indian branch | F4: Applicant | G4: Proprietary investment arm of a European bank | H4: Group in India | I4: The bank has a branch in Mumbai | J4: Requested | K4: Category I | L4: Documents | M4: Complete | N4: What extra step applies before you register it? | O4: None. Process it like any other Category I bank | P4: Send it to SEBI first, which gets RBI's comments | Q4: Ask the applicant to get RBI's approval directly | R4: Register it now, then tell RBI within 7 working days of approval | S4: B | T4: When the applicant or its group entity is a bank with a branch or representative office in India, or is a central bank, the DDP sends the form to SEBI. SEBI asks RBI for comments and passes them to the DDP to consider. This isn't repeated at continuance. | U4: The Indian branch triggers a reference to SEBI and RBI. Skipping it is a process breach. | W4: The DDP routes the form through SEBI. The applicant doesn't go to RBI itself. | X4: RBI's comments come before registration, not after it. | Y4: SEBI Operational Guidelines for FPIs and DDPs, Part A 3(i) | Z4: In case an applicant/ its group entity is (i) bank or its subsidiary and has a bank branch/representative office in India or (ii) a central bank or its subsidiary, the respective DDP shall forward the application form to SEBI. SEBI would in turn request RBI to provide its comments. Based on the comments received from RBI, SEBI would notify the comments of RBI to DDP to consider while processing such applications. | AC4: Op. Guidelines Part A 3(i) | AE4: Oct 2026 | AG4: =IF(A4="","",IF(COUNTA(O4:R4)<4,"Needs 4 options",IF(ISERROR(FIND(UPPER(S4),"ABCD"))+(LEN(S4)<>1),"Answer must be A-D",IF(OR(D4<1,D4>3),"Difficulty must be 1-3",IF(OR(N4="",T4=""),"Missing question or explanation",IF(COUNTBLANK(U4:X4)<>1,"Need 3 why-not texts",IF(INDEX(U4:X4,1,FIND(UPPER(S4),"ABCD"))<>"","Why-not filled for the answer",IF(AND(B4<>"live",B4<>"draft",B4<>"retired"),"Status must be live/draft/retired","OK")))))))) -> OK
A5: ONB/CAT/104 | B5: live | C5: II | D5: 2 | E5: Unregulated Luxembourg partnership | F5: Applicant | G5: Lindqvist Credit SCSp, Luxembourg | H5: Fund status | I5: Unregulated limited partnership | J5: Manager | K5: Luxembourg AIFM, appropriately regulated, registered with SEBI as a Category I FPI | L5: Undertaking | M5: Manager accepts responsibility for the fund's acts and omissions | N5: Which category? | O5: Category I | P5: Category II, because the fund itself is unregulated | Q5: Not eligible | R5: Category II until the fund is regulated | S5: A | T5: Under Reg 5(a)(iv)(II), an unregulated fund from a FATF member country is Category I when its manager is appropriately regulated, is registered as a Category I FPI, and takes responsibility for the fund's acts and omissions. Luxembourg is a FATF member. | V5: Reg 5(a)(iv)(II) lets an unregulated fund from a FATF country take Category I through a regulated Category I manager. | W5: Unregulated funds can register. Reg 5(b)(viii) even lists them under Category II. | X5: Category I is available now, without the fund being regulated. | Y5: SEBI (FPI) Regulations, 2019, Regulation 5(a)(iv) | Z5: (iv) Entities from the Financial Action Task Force member countries , or from any country specified by the Central Government by an order or by way of an agreement or treaty with other sovereign Governments, which are – I. appropriately regulated funds; II. unregulated funds whose investment manager is appropriately regulated and registered as a Category I foreign portfolio investor: Provided that the investment manager undertakes the responsibility of all the acts of commission or omission of such unregulated fund; | AC5: FPI Regs 2019, Reg 5(a)(iv)(II) | AE5: Oct 2026 | AG5: =IF(A5="","",IF(COUNTA(O5:R5)<4,"Needs 4 options",IF(ISERROR(FIND(UPPER(S5),"ABCD"))+(LEN(S5)<>1),"Answer must be A-D",IF(OR(D5<1,D5>3),"Difficulty must be 1-3",IF(OR(N5="",T5=""),"Missing question or explanation",IF(COUNTBLANK(U5:X5)<>1,"Need 3 why-not texts",IF(INDEX(U5:X5,1,FIND(UPPER(S5),"ABCD"))<>"","Why-not filled for the answer",IF(AND(B5<>"live",B5<>"draft",B5<>"retired"),"Status must be live/draft/retired","OK")))))))) -> OK
A6: ONB/CAT/105 | B6: live | C6: II | D6: 3 | E6: Cayman fund, New York manager | F6: Applicant | G6: Halcyon Opportunities Fund Ltd, Cayman Islands | H6: Fund status | I6: Unregulated | J6: Manager | K6: New York adviser, registered with SEBI as a Category I FPI | L6: Undertaking | M6: Manager accepts responsibility for the fund | N6: Which category? | O6: Category II, because Cayman isn't a FATF member | P6: Category I, under Reg 5(a)(v)(A) | Q6: Not eligible | R6: Category I only if Cayman regulates the fund | S6: B | T6: Reg 5(a)(v)(A) looks at the manager, not where the fund sits. An entity whose manager is from a FATF member country and is registered as a Category I FPI qualifies for Category I, provided the manager takes responsibility. Without that registration and undertaking, the fund would fall to Category II. | U6: That would be right under Reg 5(a)(iv), which looks at the fund's country. Reg 5(a)(v)(A) looks at the manager's. | W6: Nothing here fails the Reg 4 eligibility tests, and unregulated funds can register. | X6: The fund doesn't need to be regulated. The manager route gives Category I. | Y6: SEBI (FPI) Regulations, 2019, Regulation 5(a)(v) | Z6: (v) An entity (A) whose investment manager is from the Financial Action Task Force member country and such an investment manager is registered as a Category I foreign portfolio investor; or (B) which is at least seventy-five per cent owned, directly or indirectly by another entity, eligible under sub-clause (ii), (iii) and (iv) of clause (a) of this regulation and such an eligible entity is from a Financial Action Task Force member country: Provided that such an investment manager or eligible entity undertakes the responsibility of all the acts of commission or omission of the applicants seeking registration under this sub-clause. | AC6: FPI Regs 2019, Reg 5(a)(v)(A) and proviso | AE6: Oct 2026 | AG6: =IF(A6="","",IF(COUNTA(O6:R6)<4,"Needs 4 options",IF(ISERROR(FIND(UPPER(S6),"ABCD"))+(LEN(S6)<>1),"Answer must be A-D",IF(OR(D6<1,D6>3),"Difficulty must be 1-3",IF(OR(N6="",T6=""),"Missing question or explanation",IF(COUNTBLANK(U6:X6)<>1,"Need 3 why-not texts",IF(INDEX(U6:X6,1,FIND(UPPER(S6),"ABCD"))<>"","Why-not filled for the answer",IF(AND(B6<>"live",B6<>"draft",B6<>"retired"),"Status must be live/draft/retired","OK")))))))) -> OK
A7: ONB/NRI/106 | B7: live | C7: II | D7: 3 | E7: NRI general partner runs the fund | F7: Applicant | G7: Meridian Growth Fund LP, Delaware | H7: Largest NRI | I7: 20% of the corpus | J7: All NRI/OCI/RI | K7: 45% of the corpus | L7: Control | M7: An NRI is the general partner. The manager isn't registered with SEBI. | N7: Is the applicant eligible? | O7: Yes. Both percentages are inside the limits | P7: No. NRIs can't be in control of the applicant | Q7: Yes, but only if it registers as a Category II FPI instead | R7: No. Total NRI money has to stay under 25% | S7: B | T7: Three tests apply: each NRI, OCI or RI below 25%, all of them together below 50%, and none of them in control. The control test has carve-outs: an offshore fund with a SEBI NOC under the Mutual Fund Regulations, or a manager controlled by NRIs that is regulated at home and registered with SEBI as a non-investing FPI, or set up and registered in India. None applies here. | U7: The percentages pass, but the control test fails. All three tests have to be met. | W7: The control test is an eligibility condition, so changing the category doesn't fix it. | X7: 25% is the cap for a single NRI, OCI or RI. The cap on all of them together is below 50%. | Y7: SEBI Operational Guidelines for FPIs and DDPs, Part A 2(ii) | Z7: Where NRIs or OCI or RIs are constituents of the applicant – a. the contribution of a single NRI or OCI or RI shall be below twenty-five percent of the total contribution in the corpus of the applicant; b. the aggregate contribution of NRIs, OCIs and RIs shall be below fifty percent of the total contribution in the corpus of the applicant. Explanation: The contribution of RI is permitted, if made through the Liberalised Remittance Scheme (LRS) approved by Reserve Bank of India in global funds whose Indian exposure is less than 50%. c. the NRIs, OCIs and RIs shall not be in control of the applicant. | AC7: FPI Regs 2019, Reg 4(c); Op. Guidelines Part A 2(ii)(a)–(d) | AE7: Oct 2026 | AG7: =IF(A7="","",IF(COUNTA(O7:R7)<4,"Needs 4 options",IF(ISERROR(FIND(UPPER(S7),"ABCD"))+(LEN(S7)<>1),"Answer must be A-D",IF(OR(D7<1,D7>3),"Difficulty must be 1-3",IF(OR(N7="",T7=""),"Missing question or explanation",IF(COUNTBLANK(U7:X7)<>1,"Need 3 why-not texts",IF(INDEX(U7:X7,1,FIND(UPPER(S7),"ABCD"))<>"","Why-not filled for the answer",IF(AND(B7<>"live",B7<>"draft",B7<>"retired"),"Status must be live/draft/retired","OK")))))))) -> OK
A8: MON/NRI/107 | B8: live | C8: II | D8: 3 | E8: Redemptions push NRI share over 50% | F8: Holder | G8: Existing Category II FPI | H8: Event | I8: Other investors redeem; NRI/OCI share rises to 53% | J8: Breach date | K8: 1 July 2026 | L8: Status on 15 July | M8: Still 53% | N8: What timeline applies? | O8: Sell all Indian holdings within 5 trading days of the breach | P8: 90 days to fix it, then a purchase block and a 180-day exit | Q8: No action needed, because a passive breach doesn't count | R8: Stop all trading today and report the breach to SEBI | S8: B | T8: A temporary breach of the NRI/OCI/RI limits gives the FPI 90 days to comply again. If it is still in breach after 90 days, it can't make fresh purchases and must sell its positions within the following 180 days. | U8: 5 trading days is the timeline for breaching an investment limit, not for breaching the investor-mix limits. | W8: A temporary breach still counts. The 90-day period exists to fix exactly this. | X8: Nothing is blocked on day one. The FPI gets 90 days to comply first. | Y8: SEBI Operational Guidelines for FPIs and DDPs, Part A 2(ii)(f) | Z8: In case of temporary breach of above investment limits after December 31. 2020, the foreign portfolio investor shall comply with the eligibility conditions within ninety days of its breach. In case the foreign portfolio investor remains non-compliant with the said requirement even after ninety days, then no fresh purchases shall be permitted and such foreign portfolio investor shall liquidate its existing position in Indian securities market within a period of the next one hundred and eighty days. | AC8: Op. Guidelines Part A 2(ii)(f) | AE8: Oct 2026 | AG8: =IF(A8="","",IF(COUNTA(O8:R8)<4,"Needs 4 options",IF(ISERROR(FIND(UPPER(S8),"ABCD"))+(LEN(S8)<>1),"Answer must be A-D",IF(OR(D8<1,D8>3),"Difficulty must be 1-3",IF(OR(N8="",T8=""),"Missing question or explanation",IF(COUNTBLANK(U8:X8)<>1,"Need 3 why-not texts",IF(INDEX(U8:X8,1,FIND(UPPER(S8),"ABCD"))<>"","Why-not filled for the answer",IF(AND(B8<>"live",B8<>"draft",B8<>"retired"),"Status must be live/draft/retired","OK")))))))) -> OK
A9: MON/LIM/108 | B9: live | C9: IV | D9: 1 | E9: Two sister FPIs cross 10% together | F9: FPI A | G9: Holds 6.2% of Company X | H9: FPI B | I9: Holds 3.5% of Company X | J9: Link | K9: Same parent owns 60% of both | L9: Today | M9: FPI B buys another 0.6% | N9: What's the position? | O9: Fine. Each FPI is below 10% on its own, so no breach | P9: Breach. Sell the excess in 5 trading days or it all becomes FDI | Q9: Fine, as long as the aggregate FPI limit still has room | R9: Breach, and the exchange reverses B's new purchase to cure it | S9: B | T9: Common ownership above 50%, or common control, puts FPIs in one investor group, and their holdings count together against the below-10% limit on a fully diluted basis. If the excess isn't sold within 5 trading days of settlement, the group's entire investment in the company is treated as FDI, and it can't make further portfolio investment in that company. | U9: Common ownership above 50% makes them one investor group, so the limit applies to the combined 10.3%. | W9: The aggregate FPI limit is a separate cap at company level. The 10% group limit still applies. | X9: Exchange trades aren't reversed. The fix is to sell down within 5 trading days, or the holding turns into FDI. | Y9: SEBI (FPI) Regulations, 2019, Regulation 20(7) | Z9: (7) The purchase of equity shares of each company by a single foreign portfolio investor including its investor group shall be below ten per cent of the total paid-up equity capital on a fully diluted basis of the company: Provided that where the total investment under these regulations by a foreign portfolio investor including its investor group exceeds the threshold of below ten per cent of the total paid up equity capital in a listed or to be listed company on a fully diluted basis, the foreign portfolio investor shall divest the excess holding within five trading days from the date of settlement of the trades resulting in the breach: Provided further that in case the foreign portfolio investor fails to divest the excess holding, the entire investment in the company by such foreign portfolio investor including its investor group shall be considered as investment under the Foreign Direct Investment, as per the procedure specified by the Board and the foreign portfolio investor and its investor group shall not make further portfolio investment in that company under these regulations, | AC9: FPI Regs 2019, Reg 20(7), Reg 22(3) | AE9: Oct 2026 | AG9: =IF(A9="","",IF(COUNTA(O9:R9)<4,"Needs 4 options",IF(ISERROR(FIND(UPPER(S9),"ABCD"))+(LEN(S9)<>1),"Answer must be A-D",IF(OR(D9<1,D9>3),"Difficulty must be 1-3",IF(OR(N9="",T9=""),"Missing question or explanation",IF(COUNTBLANK(U9:X9)<>1,"Need 3 why-not texts",IF(INDEX(U9:X9,1,FIND(UPPER(S9),"ABCD"))<>"","Why-not filled for the answer",IF(AND(B9<>"live",B9<>"draft",B9<>"retired"),"Status must be live/draft/retired","OK")))))))) -> OK
A10: MON/LIM/109 | B10: live | C10: V | D10: 3 | E10: Two UCITS under one management company | F10: FPI A | G10: Luxembourg UCITS, holds 6% of Company Y | H10: FPI B | I10: Irish UCITS, holds 5% of Company Y | J10: Link | K10: Same management company (common control); no common ownership above 50% | L10: Both | M10: Open to retail investors | N10: Are they combined for the 10% limit? | O10: Yes. Common control makes them one investor group | P10: No. That rule doesn't apply to regulated public retail funds | Q10: Yes, unless SEBI grants these two funds a specific exemption order | R10: No, because they are domiciled in different countries | S10: B | T10: Reg 22(4) switches off the common-control rule where the FPIs are appropriately regulated public retail funds, or retail funds with regulated managers. The relief covers common control only. If they also shared more than 50% ownership, they would still be combined. | U10: Normally yes, but Reg 22(4) switches off the common-control rule for appropriately regulated public retail funds. | W10: The exemption is written into Reg 22(4) itself. No SEBI order is needed. | X10: Country doesn't decide investor groups. Ownership and control do. | Y10: SEBI (FPI) Regulations, 2019, Regulation 22(4) | Z10: (4) Notwithstanding anything contained in sub-regulation (3), the clubbing of investment limit of foreign portfolio investors having common control shall not be applicable where – (a) foreign portfolio investors are appropriately regulated public retail funds; or (b) the foreign portfolio investors are public retail funds where the majority is owned by appropriately regulated public retail fund on look through basis; or (c) foreign portfolio investors are public retail funds and investment managers of such foreign portfolio investors are appropriately regulated. Explanation - Public retail funds means (i) mutual funds or unit trusts which are open for subscription to retail investors and which do not have specific investor type requirements like accredited investors; (ii) insurance companies where segregated portfolio with one to one correlation with a single investor is not maintained; and (iii)pension funds. | AC10: FPI Regs 2019, Reg 22(4) | AE10: Oct 2026 | AG10: =IF(A10="","",IF(COUNTA(O10:R10)<4,"Needs 4 options",IF(ISERROR(FIND(UPPER(S10),"ABCD"))+(LEN(S10)<>1),"Answer must be A-D",IF(OR(D10<1,D10>3),"Difficulty must be 1-3",IF(OR(N10="",T10=""),"Missing question or explanation",IF(COUNTBLANK(U10:X10)<>1,"Need 3 why-not texts",IF(INDEX(U10:X10,1,FIND(UPPER(S10),"ABCD"))<>"","Why-not filled for the answer",IF(AND(B10<>"live",B10<>"draft",B10<>"retired"),"Status must be live/draft/retired","OK")))))))) -> OK
A11: MON/CHG/110 | B11: live | C11: V | D11: 2 | E11: Ownership change reported eight months late | F11: FPI | G11: Category I fund managed by an asset manager | H11: Event | I11: New parent bought 70% of the asset manager on 10 January 2026 | J11: Told DDP | K11: 15 September 2026 | L11: Category impact | M11: Not yet assessed | N11: What does the DDP do? | O11: Update the records. Late reporting has no consequence | P11: Re-assess eligibility and report the delay to SEBI | Q11: Cancel the registration for the late intimation | R11: Block the account permanently for the breach | S11: B | T11: Any direct or indirect change in structure, ownership or control must be reported within 7 working days. The DDP has to re-assess eligibility. Where the FPI was more than six months late, the DDP must report the case to SEBI with the reason. | U11: A delay over six months has to go to SEBI, and the change itself needs an eligibility check. | W11: DDPs don't cancel registrations. That is SEBI's decision under the Intermediaries Regulations. | X11: There's no automatic permanent block. The DDP re-assesses eligibility and escalates the delay. | Y11: SEBI Operational Guidelines for FPIs and DDPs, Part A 15 | Z11: In terms of Regulation 22(1)(c), if there is any change in the material information previously furnished by the FPI to the DDP and/or SEBI, which has a bearing on the certificate granted by the DDP on behalf of the Board or relating to any direct or indirect change in its structure or ownership or control, change in regulatory status, merger, demerger or restructuring, change in category/ sub-category / structure/ jurisdiction/ name of FPI/ beneficial ownership etc, of the FPI, it shall forthwith inform the DDP and/or the Board in writing. The DDP shall examine all such material changes and re-assess the eligibility of the FPI including requiring FPIs to seek fresh registration. However, DDP shall not process any request for change in jurisdiction of the FPI and in such cases, FPI may apply for new FPI registration. Where there is a delay of more than six months in intimation of material change by the FPI to the DDP, the DDP shall, forthwith, inform all such cases to SEBI for appropriate action, if any, along with reason for delay. | AC11: FPI Regs 2019, Reg 22(1)(c), Reg 31(2)(e); Op. Guidelines Part A 15 | AE11: Oct 2026 | AG11: =IF(A11="","",IF(COUNTA(O11:R11)<4,"Needs 4 options",IF(ISERROR(FIND(UPPER(S11),"ABCD"))+(LEN(S11)<>1),"Answer must be A-D",IF(OR(D11<1,D11>3),"Difficulty must be 1-3",IF(OR(N11="",T11=""),"Missing question or explanation",IF(COUNTBLANK(U11:X11)<>1,"Need 3 why-not texts",IF(INDEX(U11:X11,1,FIND(UPPER(S11),"ABCD"))<>"","Why-not filled for the answer",IF(AND(B11<>"live",B11<>"draft",B11<>"retired"),"Status must be live/draft/retired","OK")))))))) -> OK
A12: MON/CHG/111 | B12: live | C12: V | D12: 1 | E12: Fund moves from Dublin to Luxembourg | F12: FPI | G12: Ireland-domiciled fund | H12: Event | I12: Redomiciled to Luxembourg | J12: Request | K12: Change the country on the existing registration | L12: Holdings | M12: Listed Indian equity | N12: Can the DDP make the change? | O12: Yes. Update the registration and its country code | P12: No. It needs a new FPI registration | Q12: Yes, but only with SEBI's prior written approval | R12: Yes, because both countries are FATF members | S12: B | T12: The DDP re-assesses most material changes, but it can't process a change in the FPI's jurisdiction. The FPI has to apply for a new registration. | U12: The guidelines specifically bar DDPs from processing a change of jurisdiction. | W12: There's no SEBI approval route for this. A fresh registration is the only option. | X12: FATF membership is irrelevant here. A change of jurisdiction can't be processed on an existing registration at all. | Y12: SEBI Operational Guidelines for FPIs and DDPs, Part A 15(ii) | Z12: The DDP shall examine all such material changes and re-assess the eligibility of the FPI including requiring FPIs to seek fresh registration. However, DDP shall not process any request for change in jurisdiction of the FPI and in such cases, FPI may apply for new FPI registration. | AC12: Op. Guidelines Part A 15(ii) | AE12: Oct 2026 | AG12: =IF(A12="","",IF(COUNTA(O12:R12)<4,"Needs 4 options",IF(ISERROR(FIND(UPPER(S12),"ABCD"))+(LEN(S12)<>1),"Answer must be A-D",IF(OR(D12<1,D12>3),"Difficulty must be 1-3",IF(OR(N12="",T12=""),"Missing question or explanation",IF(COUNTBLANK(U12:X12)<>1,"Need 3 why-not texts",IF(INDEX(U12:X12,1,FIND(UPPER(S12),"ABCD"))<>"","Why-not filled for the answer",IF(AND(B12<>"live",B12<>"draft",B12<>"retired"),"Status must be live/draft/retired","OK")))))))) -> OK
A13: MON/REN/112 | B13: live | C13: II | D13: 2 | E13: Renewal fee paid seven weeks late | F13: FPI | G13: Category II fund | H13: Fees paid up to | I13: 31 August 2026 | J13: Today | K13: 20 October 2026 | L13: Request | M13: Take the fee now and continue the registration | N13: What do you tell the client? | O13: Fine. Accept the fee with a written reason for the delay | P13: Not possible. Surrender, then file a fresh application | Q13: Allowed, since it's still within 90 days of expiry | R13: Allowed, but only with SEBI's specific permission | S13: B | T13: A registration stops being valid after the date fees were paid up to, and continuance can't be applied for after expiry. The entity must surrender and apply fresh. Fees and updates should reach the DDP at least 15 days before validity ends. | U13: A reason for delay covers renewal papers that arrive late but before expiry. After expiry, continuance isn't possible. | W13: There's no 90-day grace period after expiry. | X13: The guidelines give no SEBI permission route. It has to surrender and reapply. | Y13: SEBI Operational Guidelines for FPIs and DDPs, Part A 5 | Z13: Where the FPI has not paid fees for continuance of its registration, its FPI registration shall cease to be valid after the date, up to which, the last registration fees were duly paid by the FPI. An FPI cannot apply for continuance after expiry of its registration. However, if such entity intends to have FPI registration, it will have to make a fresh application for registration after surrender of its earlier FPI registration. | AC13: Op. Guidelines Part A 5(iii)–(vi); FPI Regs 2019, Reg 9(3) | AE13: Oct 2026 | AG13: =IF(A13="","",IF(COUNTA(O13:R13)<4,"Needs 4 options",IF(ISERROR(FIND(UPPER(S13),"ABCD"))+(LEN(S13)<>1),"Answer must be A-D",IF(OR(D13<1,D13>3),"Difficulty must be 1-3",IF(OR(N13="",T13=""),"Missing question or explanation",IF(COUNTBLANK(U13:X13)<>1,"Need 3 why-not texts",IF(INDEX(U13:X13,1,FIND(UPPER(S13),"ABCD"))<>"","Why-not filled for the answer",IF(AND(B13<>"live",B13<>"draft",B13<>"retired"),"Status must be live/draft/retired","OK")))))))) -> OK
A14: ONB/CLT/113 | B14: live | C14: II | D14: 2 | E14: Broker investing for its clients | F14: Applicant | G14: Singapore-licensed broker-dealer | H14: Registration sought | I14: Category II, to invest client money | J14: Proposed clients | K14: Two individuals, one family office, one trading company | L14: Client KYC | M14: Done to Singapore standards | N14: Can all four clients invest through this registration? | O14: Yes. All four would be eligible as FPIs on their own | P14: No. The trading company can't be a client | Q14: Yes, if the broker also holds a Category I registration | R14: No. Brokers can't invest on behalf of clients at all | S14: B | T14: Regulated entities can invest for clients as Category II FPIs, but those clients must be individuals or family offices, must themselves be eligible as FPIs, and can't act for third parties. Client details go to the DDP every quarter. | U14: Being FPI-eligible is necessary but not enough. The client also has to be an individual or a family office. | W14: A Category I registration covers the broker's own money. It doesn't widen who the client registration can serve. | X14: Regulated entities, brokers included, can invest for clients through a Category II registration. | Y14: SEBI Operational Guidelines for FPIs and DDPs, Part A 3(iv) | Z14: Where such entities are undertaking investments on behalf of their clients, Category II FPI registration shall be granted subject to following conditions: Clients of FPI can only be individuals and family offices. | AC14: FPI Regs 2019, Reg 5(b)(vii); Op. Guidelines Part A 3(iv) | AE14: Oct 2026 | AG14: =IF(A14="","",IF(COUNTA(O14:R14)<4,"Needs 4 options",IF(ISERROR(FIND(UPPER(S14),"ABCD"))+(LEN(S14)<>1),"Answer must be A-D",IF(OR(D14<1,D14>3),"Difficulty must be 1-3",IF(OR(N14="",T14=""),"Missing question or explanation",IF(COUNTBLANK(U14:X14)<>1,"Need 3 why-not texts",IF(INDEX(U14:X14,1,FIND(UPPER(S14),"ABCD"))<>"","Why-not filled for the answer",IF(AND(B14<>"live",B14<>"draft",B14<>"retired"),"Status must be live/draft/retired","OK")))))))) -> OK
A15: MON/AML/114 | B15: live | C15: II | D15: 2 | E15: Major investor added to UN sanctions list | F15: FPI | G15: Category II fund | H15: Event | I15: An investor holding 30% of the corpus is added to the UN Security Council Sanctions List | J15: Pending | K15: A sell order on Indian holdings | L15: Home country | M15: Unchanged, compliant | N15: What do you do? | O15: Block new buys but let the pending sell go through | P15: Block all buying and selling, and notify SEBI | Q15: Allow trading normally until SEBI writes in | R15: Freeze only that investor's share of the fund | S15: B | T15: If the FPI or a material underlying investor comes under UNSC sanctions, the custodian must stop all further buying and selling in the account and notify SEBI immediately. | U15: Allowing sales is the rule when a home country loses compliant status. Sanctions block selling too. | W15: The custodian acts first and then notifies SEBI. It doesn't wait to hear back. | X15: The block covers the whole FPI account, not one investor's share. | Y15: SEBI Operational Guidelines for FPIs and DDPs, Part A 16(i) | Z15: Further, in case the FPI itself or its underlying investors contributing twenty-five percent or more in the corpus of the FPI or identified on the basis of control, come under the Sanctions List notified by the United Nations Security Council, custodian shall not allow any further buy/sell in the account of such FPI and shall forthwith notify such instances to SEBI. | AC15: FPI Regs 2019, Reg 4(f); Op. Guidelines Part A 16(i) | AE15: Oct 2026 | AG15: =IF(A15="","",IF(COUNTA(O15:R15)<4,"Needs 4 options",IF(ISERROR(FIND(UPPER(S15),"ABCD"))+(LEN(S15)<>1),"Answer must be A-D",IF(OR(D15<1,D15>3),"Difficulty must be 1-3",IF(OR(N15="",T15=""),"Missing question or explanation",IF(COUNTBLANK(U15:X15)<>1,"Need 3 why-not texts",IF(INDEX(U15:X15,1,FIND(UPPER(S15),"ABCD"))<>"","Why-not filled for the answer",IF(AND(B15<>"live",B15<>"draft",B15<>"retired"),"Status must be live/draft/retired","OK")))))))) -> OK
A16: MON/JUR/115 | B16: live | C16: II | D16: 1 | E16: Home country put on the FATF high-risk list | F16: FPI | G16: Category I fund | H16: Event | I16: Home country listed in FATF's public statement as high-risk | J16: Holdings | K16: Listed equity and G-Secs | L16: Fund itself | M16: No adverse findings | N16: What changes for this FPI? | O16: It must sell everything within 180 days | P16: No fresh purchases; it may hold or sell | Q16: The registration is cancelled by the DDP | R16: Nothing changes until the next renewal | S16: B | T16: When a jurisdiction stops being compliant (it leaves IOSCO, a SEBI MoU or the BIS, or FATF names it high-risk), the custodian blocks fresh purchases. The FPI may keep or sell what it holds, and the DDP reports the affected FPIs to SEBI. | U16: There's no forced sale. The FPI can keep or sell its holdings. | W16: The registration isn't cancelled. Fresh purchases are blocked until the jurisdiction is compliant again. | X16: The custodian acts as soon as the status changes, not at renewal. | Y16: SEBI Operational Guidelines for FPIs and DDPs, Part A 16(i) | Z16: If a jurisdiction, which was a compliant jurisdiction at the time of grant of registration to FPI, becomes non-compliant jurisdiction i.e. ceases to be member of IOSCO/ Bilateral Memorandum of Understanding with SEBI/ BIS or the concerned jurisdiction of FPI is listed in FATF public statement as "high risk" and "noncooperative" jurisdiction or the concerned jurisdiction of FPI then concerned Custodian shall not allow such FPIs to make fresh purchases till the time the jurisdiction/FPI is compliant with the Regulations. However, the FPI shall be allowed to sell the securities or continue to hold the securities already purchased by it. The concerned DDP shall inform to SEBI details of such FPIs upon such change. | AC16: Op. Guidelines Part A 16(i) | AE16: Oct 2026 | AG16: =IF(A16="","",IF(COUNTA(O16:R16)<4,"Needs 4 options",IF(ISERROR(FIND(UPPER(S16),"ABCD"))+(LEN(S16)<>1),"Answer must be A-D",IF(OR(D16<1,D16>3),"Difficulty must be 1-3",IF(OR(N16="",T16=""),"Missing question or explanation",IF(COUNTBLANK(U16:X16)<>1,"Need 3 why-not texts",IF(INDEX(U16:X16,1,FIND(UPPER(S16),"ABCD"))<>"","Why-not filled for the answer",IF(AND(B16<>"live",B16<>"draft",B16<>"retired"),"Status must be live/draft/retired","OK")))))))) -> OK
A17: ONB/REJ/116 | B17: live | C17: II | D17: 2 | E17: Rejected for missing papers | F17: Applicant | G17: Category II corporate body | H17: Rejected by | I17: DDP A, for incomplete documents and unpaid fee | J17: Client wants to | K17: Appeal to SEBI | L17: Days since rejection | M17: 12 | N17: What's the right route? | O17: Ask SEBI to reconsider within 30 days | P17: Fix the gaps and reapply, with any DDP | Q17: Wait six months before reapplying anywhere | R17: Reapply only through DDP A, which rejected it | S17: B | T17: An applicant can ask SEBI to reconsider within 30 days, but not when the rejection was technical: missing information or documents, or unpaid fees. Another DDP can take the application once it has checked why it was rejected and confirmed the gaps are fixed. | U17: The 30-day reconsideration route exists, but Reg 8(3) excludes technical rejections like missing documents or fees. | W17: There's no waiting period. It can reapply as soon as the gaps are fixed. | X17: Any DDP can take it, after checking the rejection reason in the depositories' shared database. | Y17: SEBI (FPI) Regulations, 2019, Regulation 8(3) | Z17: (3) The applicant, who is aggrieved by the decision of the designated depository participant under sub-regulation (1) may, within a period of thirty days from the date of receipt of communication under sub-regulation (2), apply to the Board for reconsideration of the decision of the designated depository participant: Provided that such application for reconsideration shall not be considered by the Board where the rejection was on account of technical reasons such as non-submission of complete information, documents, including non-payment of specified fees. | AC17: FPI Regs 2019, Reg 8(3); Op. Guidelines Part A 7 | AE17: Oct 2026 | AG17: =IF(A17="","",IF(COUNTA(O17:R17)<4,"Needs 4 options",IF(ISERROR(FIND(UPPER(S17),"ABCD"))+(LEN(S17)<>1),"Answer must be A-D",IF(OR(D17<1,D17>3),"Difficulty must be 1-3",IF(OR(N17="",T17=""),"Missing question or explanation",IF(COUNTBLANK(U17:X17)<>1,"Need 3 why-not texts",IF(INDEX(U17:X17,1,FIND(UPPER(S17),"ABCD"))<>"","Why-not filled for the answer",IF(AND(B17<>"live",B17<>"draft",B17<>"retired"),"Status must be live/draft/retired","OK")))))))) -> OK
... A21: MON/INV/120 | B21: live | C21: IV | D21: 1 | E21: FPI wants shares in an unlisted company | F21: FPI | G21: Category I UK pension fund | H21: Target | I21: Unlisted Indian fintech | J21: Deal | K21: Buy 4% from existing shareholders | L21: Request | M21: Book it through the FPI account | N21: Can this go through the FPI route? | O21: Yes, because it's well under the 10% limit | P21: No. Buying unlisted equity is FDI | Q21: Yes, but only with SEBI's prior approval | R21: Yes, if it's booked as an off-market transfer | S21: B | T21: The FPI route covers shares of companies that are listed, or about to be listed, on an Indian exchange. Buying shares in an unlisted company is foreign direct investment under FEMA. | U21: The 10% limit only matters for securities an FPI is allowed to buy, and unlisted equity isn't one of them. | W21: No SEBI approval brings unlisted equity into the FPI route. | X21: Off-market sales of unlisted shares are allowed for getting out, at FEMA pricing, not for buying in. | Y21: SEBI (FPI) Regulations, 2019, Regulation 20(1)(a) | Z21: 20. (1) A foreign portfolio investor shall invest only in the following securities, namely (a) shares, debentures and warrants issued by a body corporate; listed or to be listed on a recognized stock exchange in India; | AC21: FPI Regs 2019, Reg 20(1)(a); Op. Guidelines Part C 4 | AE21: Oct 2026 | AG21: =IF(A21="","",IF(COUNTA(O21:R21)<4,"Needs 4 options",IF(ISERROR(FIND(UPPER(S21),"ABCD"))+(LEN(S21)<>1),"Answer must be A-D",IF(OR(D21<1,D21>3),"Difficulty must be 1-3",IF(OR(N21="",T21=""),"Missing question or explanation",IF(COUNTBLANK(U21:X21)<>1,"Need 3 why-not texts",IF(INDEX(U21:X21,1,FIND(UPPER(S21),"ABCD"))<>"","Why-not filled for the answer",IF(AND(B21<>"live",B21<>"draft",B21<>"retired"),"Status must be live/draft/retired","OK")))))))) -> OK
A22: SWG/ELG/201 | B22: live | C22: SW | D22: 1 | E22: Luxembourg UCITS applies for SWAGAT | F22: Applicant | G22: Aurelia Global Equity, a Luxembourg SICAV authorised by the CSSF | H22: Investors | I22: Retail; no accredited-investor condition | J22: Portfolio | K22: Common pool, diversified | L22: Manager | M22: Independent management company | N22: Can it be tagged SWAGAT-FI? | O22: Yes, as a public retail fund | P22: No. Only government investors can qualify | Q22: Only after three years as a regular FPI | R22: No. UCITS have to stay in Category II | S22: A | T22: A retail fund qualifies if it is open to retail investors, runs as a blind pool with diversified investors and investments, has contributors without day-to-day control and an independent manager, and comes from a jurisdiction named in the SOP. Luxembourg UCITS are on the list. | V22: Four types qualify: government investors, retail mutual funds, insurers and pension funds. | W22: There's no waiting period. Eligible applicants can opt in when they first register. | X22: UCITS are often Category I anyway, and the SWAGAT letter is open to Category I and II FPIs alike. | Y22: SEBI circular, 16 Jan 2026 (SWAGAT-FI), para 3.2 (vi)(I) | Z22: I. The following shall be eligible for registration as SWAGAT-FI FPI a. Government or Government related investor as provided under Regulation 5(a)(i) of the FPI Regulations, 2019; b. Appropriately regulated mutual fund or unit trust open for subscription to retail investors without any specific investor type requirements like accredited investors and complying with the following conditions: i. The applicant operates as a blind pool (i.e. common portfolio) with diversified investors and investments. ii. The contributors to the applicant do not have control over day-to-day operations of the applicant and the investment manager of the applicant is independent from such contributors; | AA22: SEBI circular, 16 Jan 2026 (SWAGAT-FI), para 3.2 (vi)(II) | AB22: II. The applicant being a public retail fund is setup in identified jurisdiction and regulated by the identified statutory authority / regulatory body in such identified jurisdiction. The list of identified jurisdictions and identified statutory authority / regulatory body shall be spelt out in the Standard Operating Procedure framed and adopted by Custodians and Designated Depository Participants Standards Setting Forum (CDSSF) in consultation with SEBI. | AC22: SEBI circular 16 Jan 2026, para 3.2 (vi)(I)–(II); SWAGAT SOP 27 May 2026, Annex B | AE22: Oct 2026 | AG22: =IF(A22="","",IF(COUNTA(O22:R22)<4,"Needs 4 options",IF(ISERROR(FIND(UPPER(S22),"ABCD"))+(LEN(S22)<>1),"Answer must be A-D",IF(OR(D22<1,D22>3),"Difficulty must be 1-3",IF(OR(N22="",T22=""),"Missing question or explanation",IF(COUNTBLANK(U22:X22)<>1,"Need 3 why-not texts",IF(INDEX(U22:X22,1,FIND(UPPER(S22),"ABCD"))<>"","Why-not filled for the answer",IF(AND(B22<>"live",B22<>"draft",B22<>"retired"),"Status must be live/draft/retired","OK")))))))) -> OK
A23: SWG/ELG/202 | B23: live | C23: SW | D23: 2 | E23: Irish AIF sold only to qualified investors | F23: Applicant | G23: Irish AIF authorised by the Central Bank of Ireland | H23: Marketing | I23: Qualified investors only, as noted on the Central Bank register | J23: Portfolio | K23: Diversified | L23: Current status | M23: Category I FPI | N23: Does it qualify for SWAGAT-FI? | O23: Yes. It's regulated and based in a FATF member country | P23: No. A qualified-investor fund isn't a public retail fund | Q23: Yes, as long as it gives a signed declaration to the DDP | R23: Yes, because it's already registered with SEBI as a Category I FPI | S23: B | T23: The SOP says an Irish AIF marketed to qualified investors, as shown on the Central Bank of Ireland register, is not a public retail fund. It stays a regular FPI. | U23: Being regulated in a FATF country earns Category I. SWAGAT also needs the fund to be open to retail investors. | W23: The DDP can't rely on a declaration, and here the regulator's register says the opposite. | X23: Category I status doesn't make it a public retail fund. | Y23: CDSSF SOP for SWAGAT-FI, 27 May 2026, Annex B (Ireland) | Z23: In case an AIF is marketed to qualified investors, the same is reflected on the Central Bank of Ireland website in the notes section. (such notification is available at umbrella fund level and not sub fund level) Sample case provided below. Such cases shall not be considered PRFs. Other AIFs are retail and considered as RAIF. | AC23: SWAGAT SOP 27 May 2026, Annex B (Ireland) | AE23: Oct 2026 | AG23: =IF(A23="","",IF(COUNTA(O23:R23)<4,"Needs 4 options",IF(ISERROR(FIND(UPPER(S23),"ABCD"))+(LEN(S23)<>1),"Answer must be A-D",IF(OR(D23<1,D23>3),"Difficulty must be 1-3",IF(OR(N23="",T23=""),"Missing question or explanation",IF(COUNTBLANK(U23:X23)<>1,"Need 3 why-not texts",IF(INDEX(U23:X23,1,FIND(UPPER(S23),"ABCD"))<>"","Why-not filled for the answer",IF(AND(B23<>"live",B23<>"draft",B23<>"retired"),"Status must be live/draft/retired","OK")))))))) -> OK
A24: SWG/ELG/203 | B24: live | C24: SW | D24: 2 | E24: Insurer with unit-linked sleeves | F24: Applicant | G24: Regulated life insurer | H24: India money | I24: Own funds, plus unit-linked portfolios each tied to a single policyholder | J24: Home regulator | K24: Insurance supervisor in a permitted jurisdiction | L24: Requested | M24: SWAGAT-FI | N24: Is it eligible? | O24: Yes. Regulated insurers always qualify | P24: No. The segregated portfolios rule it out | Q24: Yes, by applying as a pension fund instead | R24: Yes, if unit-linked money is under 50% | S24: B | T24: The insurance route covers an appropriately regulated insurer investing its own funds without segregated portfolios, and the insurer has to show evidence of that. Portfolios each tied to one policyholder fail the test. | U24: Only insurers investing their own funds, with no segregated portfolios, qualify. | W24: An insurer isn't a pension fund, and a different label doesn't remove the segregated portfolios. | X24: There's no percentage threshold. Any segregated portfolio fails the test. | Y24: SEBI circular, 16 Jan 2026 (SWAGAT-FI), para 3.2 (vi)(I)(c) | Z24: c. Appropriately regulated insurance company investing its own funds and does not have segregated portfolios; | AC24: SEBI circular 16 Jan 2026, para 3.2 (vi)(I)(c); SWAGAT SOP, section 8 | AE24: Oct 2026 | AG24: =IF(A24="","",IF(COUNTA(O24:R24)<4,"Needs 4 options",IF(ISERROR(FIND(UPPER(S24),"ABCD"))+(LEN(S24)<>1),"Answer must be A-D",IF(OR(D24<1,D24>3),"Difficulty must be 1-3",IF(OR(N24="",T24=""),"Missing question or explanation",IF(COUNTBLANK(U24:X24)<>1,"Need 3 why-not texts",IF(INDEX(U24:X24,1,FIND(UPPER(S24),"ABCD"))<>"","Why-not filled for the answer",IF(AND(B24<>"live",B24<>"draft",B24<>"retired"),"Status must be live/draft/retired","OK")))))))) -> OK
A25: SWG/ELG/204 | B25: live | C25: SW | D25: 3 | E25: Manager's own seed money in the fund | F25: Applicant | G25: Singapore authorised collective investment scheme, retail | H25: Manager stake | I25: 4%, seeded as skin in the game | J25: Manager | K25: Same group as the fund's sponsor | L25: Other investors | M25: Diversified retail | N25: Does either fact block SWAGAT-FI? | O25: Yes. The manager is a contributor, so the manager isn't independent | P25: No. Skin-in-the-game money and a same-group manager are both allowed | Q25: Yes. The manager must come from outside the sponsor's group to be independent | R25: Only if the stake exceeds 2% | S25: B | T25: The SOP clarifies that the test of contributors not controlling the fund ignores a manager's skin-in-the-game money. And the independence test doesn't stop a manager from the FPI's own group from managing or controlling the fund. | U25: The SOP leaves skin-in-the-game money out of the control and independence tests. | W25: The SOP says a manager from the same group doesn't breach independence. | X25: The SOP sets no percentage threshold for skin in the game. | Y25: CDSSF SOP for SWAGAT-FI, 27 May 2026, Section 3 B.1(b)–(c) | Z25: b. The requirement that the contributors to the applicant should not have control over day-to-day operations of the applicant shall not apply in respect of contributions made by the Investment Manager to the fund solely for the purpose of “skin in the game.” requirements, if any. c. The requirement that the applicant's Investment Manager being independent of the contributors to the applicant shall not be construed to prohibit an Investment Manager belonging to the same group as the FPI from managing and/ or controlling the fund. | AC25: SWAGAT SOP 27 May 2026, section 3 B.1(b)–(c) | AE25: Oct 2026 | AG25: =IF(A25="","",IF(COUNTA(O25:R25)<4,"Needs 4 options",IF(ISERROR(FIND(UPPER(S25),"ABCD"))+(LEN(S25)<>1),"Answer must be A-D",IF(OR(D25<1,D25>3),"Difficulty must be 1-3",IF(OR(N25="",T25=""),"Missing question or explanation",IF(COUNTBLANK(U25:X25)<>1,"Need 3 why-not texts",IF(INDEX(U25:X25,1,FIND(UPPER(S25),"ABCD"))<>"","Why-not filled for the answer",IF(AND(B25<>"live",B25<>"draft",B25<>"retired"),"Status must be live/draft/retired","OK")))))))) -> OK
A26: SWG/CNV/205 | B26: live | C26: SW | D26: 2 | E26: Sovereign fund converts to SWAGAT | F26: FPI | G26: Category I sovereign wealth fund, registered under Reg 5(a)(i) in 2021 | H26: Next renewal | I26: March 2027 | J26: Request | K26: Convert to SWAGAT-FI | L26: Changes | M26: None | N26: What does it need to submit and pay? | O26: A fresh KYC pack for the DDP, plus the US$2,500 SWAGAT fee | P26: A declaration of intent only, with no fee now | Q26: A full re-registration with the DDP | R26: A one-time conversion fee of US$250 | S26: B | T26: An FPI already registered as a government or government-related investor only declares its intent, using the SWAGAT requisition letter, with no further documents. No fee is due on transition. SEBI fees fall due at the next renewal after a 10-year block. | U26: A government investor that's already registered needs no further documents, and no fee is due at transition. | W26: Converting is an application to the existing DDP, not a new registration. | X26: There's no conversion fee. US$250 is the regular Category II registration fee. | Y26: CDSSF SOP for SWAGAT-FI, 27 May 2026, Section 3 B.6(a) | Z26: a. Where existing FPIs transitions to SWAGAT-FI, the FPI is not required to pay any fees at the time of transition. The applicable SEBI fees will be paid at the next renewal date after a block of 10 years. | AC26: SWAGAT SOP, section 3 A.2 and B.6(a), section 8 row 1 | AE26: Oct 2026 | AG26: =IF(A26="","",IF(COUNTA(O26:R26)<4,"Needs 4 options",IF(ISERROR(FIND(UPPER(S26),"ABCD"))+(LEN(S26)<>1),"Answer must be A-D",IF(OR(D26<1,D26>3),"Difficulty must be 1-3",IF(OR(N26="",T26=""),"Missing question or explanation",IF(COUNTBLANK(U26:X26)<>1,"Need 3 why-not texts",IF(INDEX(U26:X26,1,FIND(UPPER(S26),"ABCD"))<>"","Why-not filled for the answer",IF(AND(B26<>"live",B26<>"draft",B26<>"retired"),"Status must be live/draft/retired","OK")))))))) -> OK
A27: SWG/FEE/206 | B27: live | C27: SW | D27: 3 | E27: New applicant wants FPI and FVCI | F27: Applicant | G27: Regulated pension fund, new to India | H27: Wants | I27: SWAGAT-FI FPI and SWAGAT-FI FVCI | J27: PAN | K27: One PAN for the entity | L27: Question | M27: Upfront SEBI fee | N27: What is the fresh registration fee? | O27: US$2,500 for 3 years | P27: US$5,000, covering 10 years | Q27: US$2,600, covering 10 years | R27: US$2,500 every year | S27: B | T27: A SWAGAT-FI pays for 10 years in advance: US$2,500 for FPI only, US$2,500 for FVCI only, or US$5,000 for both, plus taxes. Renewal is US$2,500, US$100 or US$2,600. | U27: US$2,500 per 3 years is the regular Category I fee. SWAGAT fees cover 10 years, and this applicant wants both registrations. | W27: US$2,600 is the renewal fee for both, not the fresh fee. | X27: SWAGAT fees are paid once for the 10-year block, not every year. | Y27: CDSSF SOP for SWAGAT-FI, 27 May 2026, Section 3 B.5 (fee table, reformatted) | Z27: SWAGAT-FI will pay only for 10 years in advance, along with applicable taxes (amounts in USD). Registration fees (fresh): Only FPI 2500 · Only FVCI 2500 · FPI and FVCI 5000. Renewal: Only FPI 2500 · Only FVCI 100 · FPI and FVCI 2600. *For the same entity there will be one PAN, and fees would apply only once. | AC27: SWAGAT SOP 27 May 2026, section 3 B.5 | AE27: Oct 2026 | AG27: =IF(A27="","",IF(COUNTA(O27:R27)<4,"Needs 4 options",IF(ISERROR(FIND(UPPER(S27),"ABCD"))+(LEN(S27)<>1),"Answer must be A-D",IF(OR(D27<1,D27>3),"Difficulty must be 1-3",IF(OR(N27="",T27=""),"Missing question or explanation",IF(COUNTBLANK(U27:X27)<>1,"Need 3 why-not texts",IF(INDEX(U27:X27,1,FIND(UPPER(S27),"ABCD"))<>"","Why-not filled for the answer",IF(AND(B27<>"live",B27<>"draft",B27<>"retired"),"Status must be live/draft/retired","OK")))))))) -> OK
A28: SWG/KYC/207 | B28: live | C28: SW | D28: 1 | E28: Custodian diary shows a 2029 KYC review | F28: FPI | G28: SWAGAT-FI pension fund, registered June 2026 | H28: Custodian diary | I28: KYC review: June 2029 | J28: Risk rating | K28: Low | L28: Custodian policy | M28: No special rule | N28: Is the 2029 date right? | O28: Yes. KYC review is every 3 years for every FPI | P28: No. The default for SWAGAT-FIs is every 10 years | Q28: No. Once tagged SWAGAT-FI, it never needs a KYC review again | R28: Yes, but only because it's a pension fund | S28: B | T28: For SWAGAT-FIs, both continuance and KYC review move to a 10-year cycle. The SOP leaves room for a different period set by RBI, for RBI-regulated entities, or by the DDP's own risk policy. | U28: Three years is the usual cycle for regular, lower-risk FPIs. SWAGAT-FIs move to 10 years. | W28: The review still happens, every 10 years by default. | X28: The 10-year cycle applies to every type of SWAGAT-FI, pension funds included. | Y28: SEBI circular, 16 Jan 2026 (SWAGAT-FI), para 3.4 | Z28: In case of SWAGAT-FI FPI, periodicity of KYC review by custodians shall be 10 years. | AC28: Circular 16 Jan 2026, paras 3.3–3.4; SWAGAT SOP, section 3 B.2 | AE28: Oct 2026 | AG28: =IF(A28="","",IF(COUNTA(O28:R28)<4,"Needs 4 options",IF(ISERROR(FIND(UPPER(S28),"ABCD"))+(LEN(S28)<>1),"Answer must be A-D",IF(OR(D28<1,D28>3),"Difficulty must be 1-3",IF(OR(N28="",T28=""),"Missing question or explanation",IF(COUNTBLANK(U28:X28)<>1,"Need 3 why-not texts",IF(INDEX(U28:X28,1,FIND(UPPER(S28),"ABCD"))<>"","Why-not filled for the answer",IF(AND(B28<>"live",B28<>"draft",B28<>"retired"),"Status must be live/draft/retired","OK")))))))) -> OK
A29: SWG/NRI/208 | B29: live | C29: SW | D29: 3 | E29: Resident Indian money in a SWAGAT fund | F29: FPI | G29: SWAGAT-FI retail fund | H29: Largest NRI | I29: 30% of the corpus | J29: Resident Indians | K29: Individuals investing through LRS | L29: Fund's India exposure | M29: 65% | N29: Where's the problem? | O29: The NRI at 30%, which breaks the 25% single-investor cap | P29: The resident Indian money, given 65% India exposure | Q29: Nothing. SWAGAT-FIs are exempt from all contributor rules | R29: Both the NRI stake and the resident Indian money | S29: B | T29: The per-investor and combined NRI/OCI/RI caps don't apply to SWAGAT-FIs. But one condition stays: resident Indian individuals can only invest through LRS, and only in global funds whose India exposure is below 50%. At 65%, this fund fails. | U29: The per-investor and combined caps are switched off for SWAGAT-FIs. | W29: The LRS condition for resident Indians still applies. | X29: Only the resident Indian money fails. The NRI stake is fine. | Y29: SEBI circular, 16 Jan 2026 (SWAGAT-FI), para 3.1 | Z29: db. The provision mentioned at (b) above shall not apply to SWAGAT-FI FPI. However, it shall be subject to the provision that contribution of resident Indian individuals shall be made through the LRS notified by RBI and shall be in global funds whose Indian exposure is less than 50%. | AC29: Circular 16 Jan 2026, para 3.1 (Master Circular Part A para 1(ii)(db)) | AE29: Oct 2026 | AG29: =IF(A29="","",IF(COUNTA(O29:R29)<4,"Needs 4 options",IF(ISERROR(FIND(UPPER(S29),"ABCD"))+(LEN(S29)<>1),"Answer must be A-D",IF(OR(D29<1,D29>3),"Difficulty must be 1-3",IF(OR(N29="",T29=""),"Missing question or explanation",IF(COUNTBLANK(U29:X29)<>1,"Need 3 why-not texts",IF(INDEX(U29:X29,1,FIND(UPPER(S29),"ABCD"))<>"","Why-not filled for the answer",IF(AND(B29<>"live",B29<>"draft",B29<>"retired"),"Status must be live/draft/retired","OK")))))))) -> OK
A30: SWG/EVD/209 | B30: live | C30: SW | D30: 2 | E30: US fund ticks every box itself | F30: Applicant | G30: US open-end mutual fund, SEC-registered | H30: Submitted | I30: SWAGAT letter with Yes for all five retail-fund conditions | J30: Prospectus | K30: Not provided | L30: Request | M30: Tag as SWAGAT-FI this week | N30: Can the DDP approve on this? | O30: Yes. The applicant's own declaration is enough | P30: No. The DDP needs evidence such as the prospectus | Q30: Yes, because SEC registration proves retail status | R30: No. US funds can't be SWAGAT-FIs at all | S30: B | T30: Where the home rules don't show a condition, the applicant must provide a certificate from its regulator or its own documents, such as the prospectus, with the relevant clauses marked. The DDP can't rely on a declaration alone. For US funds the SOP marks openness to retail investors as To Be Verified. | U30: The SOP specifically says the DDP can't rely on a mere declaration. | W30: SEC registration doesn't settle retail access. Some registered funds are sold only to accredited investors. | X30: US funds are covered in the SOP's Annex B. They can qualify with evidence. | Y30: CDSSF SOP for SWAGAT-FI, 27 May 2026, Section 3 B.1(a) | Z30: a. Indicative guidelines for qualifying as a SWAGAT-FI, wherever available under the applicable Acts/ Regulations and/ or on regulatory websites in the home jurisdiction of the funds, are provided in annexures to this SOP. Where such conditions are not evidenced in the above material, the FPI / FVCI should provide to their DDP the original or certified/ attested copy of the certificate/ document evidencing that the FPI/ FVCI meets the eligibility requirement, with the respective provisions clearly identified for verification by the DDP. Such certificate/ document shall be issued by the concerned regulator/ authority or shall form a part of constitutive documents of the FPI / FVCI (including the Prospectus / Information Memorandum (IM)/ Offer Document etc.). The DDP shall obtain sufficient supporting documentation in such cases and not rely on mere declaration by the FPI / FVCI, and the certification/ attestation shall be carried out as authorised in the Master Circular. | AC30: SWAGAT SOP 27 May 2026, section 3 B.1(a); Annex B (USA) | AE30: Oct 2026 | AG30: =IF(A30="","",IF(COUNTA(O30:R30)<4,"Needs 4 options",IF(ISERROR(FIND(UPPER(S30),"ABCD"))+(LEN(S30)<>1),"Answer must be A-D",IF(OR(D30<1,D30>3),"Difficulty must be 1-3",IF(OR(N30="",T30=""),"Missing question or explanation",IF(COUNTBLANK(U30:X30)<>1,"Need 3 why-not texts",IF(INDEX(U30:X30,1,FIND(UPPER(S30),"ABCD"))<>"","Why-not filled for the answer",IF(AND(B30<>"live",B30<>"draft",B30<>"retired"),"Status must be live/draft/retired","OK")))))))) -> OK
